#VRML_SIM R2025a utf8

EXTERNPROTO "https://raw.githubusercontent.com/cyberbotics/webots/R2023b/projects/objects/backgrounds/protos/TexturedBackground.proto"
EXTERNPROTO "https://raw.githubusercontent.com/cyberbotics/webots/R2023b/projects/objects/backgrounds/protos/TexturedBackgroundLight.proto"
EXTERNPROTO "https://raw.githubusercontent.com/cyberbotics/webots/R2023b/projects/objects/floors/protos/RectangleArena.proto"

WorldInfo {
  info [
    "Simple e-puck simulation that can be controlled with ROS2."
  ]
  title "ROS2 simulation of the e-puck robot"
  basicTimeStep 20
}
Viewpoint {
  orientation -0.5685874414442981 0.5910584018053378 0.5721523285691904 2.068476156460521
  position 0.20808585194499646 -0.7710719237425759 14.527911336314421
}
TexturedBackground {
}
TexturedBackgroundLight {
}
RectangleArena {
  floorSize 4 4
}
Solid {
  translation 0 0 0.1
  children [
    Shape {
      appearance Appearance {
        material Material {
          diffuseColor 0.6 0.3 0.2
        }
      }
      geometry Cylinder {
        height 0.2
        radius 0.3
      }
    }
  ]
  boundingObject Cylinder {
    height 0.1
    radius 0.05
  }
}
DEF ROBOT_1 Robot {
  translation 0.75 0.75 -0.00112615
  children [
    Camera {
    }
    RangeFinder {
      name "rangeFinder"
    }
    Lidar {
      translation 0 0 0.05
      name "lidar2D"
      horizontalResolution 360
      fieldOfView 6.28
      numberOfLayers 1
    }
    HingeJoint {
      jointParameters HingeJointParameters {
        axis 0 1 0
        anchor 0 0 0.025
      }
      device [
        RotationalMotor {
          name "left wheel motor"
        }
        PositionSensor {
          name "left wheel encoder"
        }
      ]
      endPoint Solid {
        translation 0 0.044999999999999984 0.025
        rotation 0 -1 0 1.7881393432617193e-07
        children [
          DEF WHEEL Pose {
            rotation 1 0 0 1.5707996938995747
            children [
              Shape {
                appearance PBRAppearance {
                  baseColor 1 0 0
                  roughness 1
                  metalness 0
                }
                geometry Cylinder {
                  height 0.0001
                  radius 0.024
                }
              }
            ]
          }
        ]
        name "left wheel"
        boundingObject USE WHEEL
        physics Physics {
        }
      }
    }
    HingeJoint {
      jointParameters HingeJointParameters {
        axis 0 1 0
        anchor 0 0 0.025
      }
      device [
        RotationalMotor {
          name "right wheel motor"
        }
        PositionSensor {
          name "right wheel encoder"
        }
      ]
      endPoint Solid {
        translation 0 -0.044999999999999984 0.025
        rotation 0 1 0 0
        children [
          USE WHEEL
        ]
        name "right wheel"
        boundingObject USE WHEEL
        physics Physics {
        }
      }
    }
    Pose {
      translation 0 0 0.0415
      children [
        Shape {
          appearance PBRAppearance {
            baseColor 0 0 1
            roughness 1
            metalness 0
          }
          geometry DEF BODY Cylinder {
            height 0.08
            radius 0.045
          }
        }
      ]
    }
  ]
  boundingObject Pose {
    translation 0 0 0.0415
    children [
      USE BODY
    ]
  }
  physics Physics {
  }
  controller "<extern>"
  supervisor TRUE
}
