#VRML_SIM R2025a utf8

EXTERNPROTO "https://raw.githubusercontent.com/cyberbotics/webots/R2023b/projects/objects/backgrounds/protos/TexturedBackground.proto"
EXTERNPROTO "https://raw.githubusercontent.com/cyberbotics/webots/R2023b/projects/objects/backgrounds/protos/TexturedBackgroundLight.proto"
EXTERNPROTO "https://raw.githubusercontent.com/cyberbotics/webots/R2023b/projects/objects/floors/protos/RectangleArena.proto"
EXTERNPROTO "https://raw.githubusercontent.com/cyberbotics/webots/R2023b/projects/objects/factory/containers/protos/WoodenBox.proto"

WorldInfo {
  info [
    "Simple e-puck simulation that can be controlled with ROS2."
  ]
  title "ROS2 simulation of the e-puck robot"
  basicTimeStep 20
}
Viewpoint {
  orientation -0.41231078918158254 0.21062111788650378 0.8863625431078979 2.2912703948601707
  position 1.345328055634804 -2.7003799758801814 3.7192082944676064
}
TexturedBackground {
}
TexturedBackgroundLight {
}
RectangleArena {
  floorSize 1.5 1.5
}
WoodenBox {
  translation -0.2 0.1 0.05
  rotation 0 0 1 0.7853
  name "wooden box(1)"
  size 0.1 0.1 0.1
}
WoodenBox {
  translation 0.39 -0.24 0.05
  rotation 0 0 1 0.3927
  name "wooden box(2)"
  size 0.1 0.2 0.1
}
DEF ROBOT_1 Robot {
  translation -9.15719245155825e-08 1.7978260805955264e-11 -0.00011400007550241287
  rotation 1.65513951447425e-07 -0.9999999999999863 -2.7163340181627438e-09 0.030916872486638575
  children [
    Camera {
    }
    RangeFinder {
      name "rangeFinder"
    }
    Lidar {
      translation 0 0 0.05
      name "lidar2D"
      horizontalResolution 1000
      fieldOfView 6.28
      numberOfLayers 1
      maxRange 5
    }
    HingeJoint {
      jointParameters HingeJointParameters {
        position 2.2209266766058227e-07
        axis 0 1 0
        anchor 0 0 0.025
      }
      device [
        RotationalMotor {
          name "left wheel motor"
        }
        PositionSensor {
          name "left wheel encoder"
        }
      ]
      endPoint Solid {
        translation 0 0.04499999999999999 0.025
        rotation 0 -1 0 6.279504925689784
        children [
          DEF WHEEL Pose {
            rotation 1 0 0 1.5707996938995747
            children [
              Shape {
                appearance PBRAppearance {
                  baseColor 1 0 0
                  roughness 1
                  metalness 0
                }
                geometry Cylinder {
                  height 0.0001
                  radius 0.025
                }
              }
            ]
          }
        ]
        name "left wheel"
        boundingObject USE WHEEL
        physics Physics {
        }
        linearVelocity 1.1039727371234864e-14 3.79442021982579e-13 -2.1816168158983882e-14
        angularVelocity -2.030069549813456e-11 7.772958144712978e-14 -4.1643251036179053e-13
      }
    }
    HingeJoint {
      jointParameters HingeJointParameters {
        position 1.1373949765353832e-11
        axis 0 1 0
        anchor 0 0 0.025
      }
      device [
        RotationalMotor {
          name "right wheel motor"
        }
        PositionSensor {
          name "right wheel encoder"
        }
      ]
      endPoint Solid {
        translation 0 -0.045 0.025
        rotation 0 1 0 0.3427261558557248
        children [
          USE WHEEL
        ]
        name "right wheel"
        boundingObject USE WHEEL
        physics Physics {
        }
        linearVelocity -1.5301659826307495e-15 4.157661858284332e-13 7.189470070136828e-16
        angularVelocity -9.084413965822662e-12 7.721509999331101e-14 1.990732455838345e-12
      }
    }
    Pose {
      translation 0 0 0.0415
      children [
        Shape {
          appearance PBRAppearance {
            baseColor 0 0 1
            roughness 1
            metalness 0
          }
          geometry DEF BODY Cylinder {
            height 0.08
            radius 0.045
          }
        }
      ]
    }
  ]
  boundingObject Pose {
    translation 0 0 0.0415
    children [
      USE BODY
    ]
  }
  physics Physics {
  }
  controller "<extern>"
  supervisor TRUE
  linearVelocity -1.3686992045926942e-14 5.910831655254284e-13 6.491996386855572e-15
  angularVelocity -1.4129675691693917e-11 7.724695085163875e-14 6.460555971371742e-13
}
